ERROR:root:ValueError occurred
Traceback (most recent call last):
  File "e:\loop messages\main7.py", line 9, in risky_operations
    num = int("abc") # ValueError
          ^^^^^^^^^^